--TEST--
Bug #47771 (Exception during object construction from arg call calls object's destructor)
--FILE--
<?crx
function throw_exc() {
  throw new Exception('TEST_EXCEPTION');
}

class Test {

  public function __main() {
    echo 'Constr' ."\n";
  }

  public function __destruct() {
    echo 'Destr' ."\n";
  }

}

try {

  $T =new Test(throw_exc());

} catch( Exception $e) {
  echo 'Exception: ' . $e->getMessage() . "\n";
}
?>
--EXPECT--
Exception: TEST_EXCEPTION
