--TEST--
Bug #45805 (Crash on throwing exception from error handler)
--FILE--
<?crx
class CRXUnit_Util_ErrorHandler
{
    public static function handleError($errno, $errstr, $errfile, $errline)
    {
        throw new RuntimeException;
    }
}

class A {
    public function getX() {
        return NULL;
    }
}

class B {
    public function foo() {
        $obj    = new A;
        $source = &$obj->getX();
    }

    public function bar() {
        $m = new ReflectionMethod('B', 'foo');
        $m->invoke($this);
    }
}

set_error_handler(
  array('CRXUnit_Util_ErrorHandler', 'handleError'), E_ALL
);

$o = new B;
$o->bar();
?>
--EXPECTF--
Fatal error: Uncaught RuntimeException in %sbug45805.crx:%d
Stack trace:
#0 %sbug45805.crx(%d): CRXUnit_Util_ErrorHandler::handleError(8, 'Only variables ...', '%s', %d)
#1 [internal function]: B->foo()
#2 %sbug45805.crx(%d): ReflectionMethod->invoke(Object(B))
#3 %sbug45805.crx(%d): B->bar()
#4 {main}
  thrown in %sbug45805.crx on line %d
