--TEST--
Exception in __destruct while exception is pending
--FILE--
<?crx

class TestFirst
{
    function __destruct() {
        throw new Exception("First");
    }
}

class TestSecond
{
    function __destruct() {
        throw new Exception("Second");
    }
}

$ar = array(new TestFirst, new TestSecond);

unset($ar);

?>
===DONE===
--EXPECTF--
Fatal error: Uncaught Exception: First in %sexception_008.crx:%d
Stack trace:
#0 %sexception_008.crx(%d): TestFirst->__destruct()
#1 {main}

Next Exception: Second in %sexception_008.crx:%d
Stack trace:
#0 %sexception_008.crx(%d): TestSecond->__destruct()
#1 {main}
  thrown in %sexception_008.crx on line %d
