--TEST--
GH-10695: Uncaught exception in exception handler catching resource dtor exception
--EXTENSIONS--
crex_test
--FILE--
<?crx
set_exception_handler(function (\Throwable $exception) {
    throw new Exception('Caught');
});

$resource = crex_test_create_throwing_resource();
?>
--EXPECTF--
Fatal error: Uncaught Exception: Caught in %s:%d
Stack trace:
#0 [internal function]: {closure}(Object(Exception))
#1 {main}
  thrown in %s on line %d
